<sdf version='1.9'>
  <model name='gdgu_robot'>
    <link name='base_link'>
      <inertial>
        <pose>0.0422115384615384 0 -0.01259615384615384 0 0 0</pose>
        <mass>1.04</mass>
        <inertia>
          <ixx>0.01051322371794872</ixx>
          <ixy>0</ixy>
          <ixz>-0.0012019711538461531</ixz>
          <iyy>0.038237637179487208</iyy>
          <iyz>0</iyz>
          <izz>0.048496013461538499</izz>
        </inertia>
      </inertial>
      <collision name='base_link_fixed_joint_lump__chassis_link_collision'>
        <pose>0 0 -0.009000000000000001 0 0 0</pose>
        <geometry>
          <box>
            <size>0.35 0.29 0.002</size>
          </box>
        </geometry>
        <surface>
          <contact>
            <ode/>
          </contact>
          <friction>
            <ode/>
          </friction>
        </surface>
      </collision>
      <collision name='base_link_fixed_joint_lump__caster_wheel1_link_collision_1'>
        <pose>-0.16 0.125 -0.04 0 0 0</pose>
        <geometry>
          <sphere>
            <radius>0.01</radius>
          </sphere>
        </geometry>
        <surface>
          <contact>
            <ode/>
          </contact>
          <friction>
            <ode>
              <mu>0.001</mu>
              <mu2>0.001</mu2>
            </ode>
          </friction>
        </surface>
      </collision>
      <collision name='base_link_fixed_joint_lump__connector_cw1_link_collision_2'>
        <pose>-0.16 0.125 -0.02 0 0 0</pose>
        <geometry>
          <cylinder>
            <length>0.021999999999999999</length>
            <radius>0.0050000000000000001</radius>
          </cylinder>
        </geometry>
      </collision>
      <collision name='base_link_fixed_joint_lump__caster_wheel2_link_collision_3'>
        <pose>-0.16 -0.125 -0.04 0 0 0</pose>
        <geometry>
          <sphere>
            <radius>0.01</radius>
          </sphere>
        </geometry>
        <surface>
          <contact>
            <ode/>
          </contact>
          <friction>
            <ode>
              <mu>0.001</mu>
              <mu2>0.001</mu2>
            </ode>
          </friction>
        </surface>
      </collision>
      <collision name='base_link_fixed_joint_lump__connector_cw2_link_collision_4'>
        <pose>-0.16 -0.125 -0.02 0 0 0</pose>
        <geometry>
          <cylinder>
            <length>0.021999999999999999</length>
            <radius>0.0050000000000000001</radius>
          </cylinder>
        </geometry>
      </collision>
      <collision name='base_link_fixed_joint_lump__caster_wheel3_link_collision_5'>
        <pose>0.13 0.125 -0.04 0 0 0</pose>
        <geometry>
          <sphere>
            <radius>0.01</radius>
          </sphere>
        </geometry>
        <surface>
          <contact>
            <ode/>
          </contact>
          <friction>
            <ode>
              <mu>0.001</mu>
              <mu2>0.001</mu2>
            </ode>
          </friction>
        </surface>
      </collision>
      <collision name='base_link_fixed_joint_lump__connector_cw3_link_collision_6'>
        <pose>0.13 0.125 -0.02 0 0 0</pose>
        <geometry>
          <cylinder>
            <length>0.021999999999999999</length>
            <radius>0.0050000000000000001</radius>
          </cylinder>
        </geometry>
      </collision>
      <collision name='base_link_fixed_joint_lump__caster_wheel4_link_collision_7'>
        <pose>0.13 -0.125 -0.04 0 0 0</pose>
        <geometry>
          <sphere>
            <radius>0.01</radius>
          </sphere>
        </geometry>
        <surface>
          <contact>
            <ode/>
          </contact>
          <friction>
            <ode>
              <mu>0.001</mu>
              <mu2>0.001</mu2>
            </ode>
          </friction>
        </surface>
      </collision>
      <collision name='base_link_fixed_joint_lump__connector_cw4_link_collision_8'>
        <pose>0.13 -0.125 -0.02 0 0 0</pose>
        <geometry>
          <cylinder>
            <length>0.021999999999999999</length>
            <radius>0.0050000000000000001</radius>
          </cylinder>
        </geometry>
      </collision>
      <collision name='base_link_fixed_joint_lump__stepper_link_collision_9'>
        <pose>0.165 0 0 0 0 0</pose>
        <geometry>
          <box>
            <size>0.02 0.01 0.02</size>
          </box>
        </geometry>
        <surface>
          <contact>
            <ode/>
          </contact>
          <friction>
            <ode/>
          </friction>
        </surface>
      </collision>
      <visual name='base_link_fixed_joint_lump__chassis_link_visual'>
        <pose>0 0 -0.009000000000000001 0 0 0</pose>
        <geometry>
          <box>
            <size>0.35 0.29 0.002</size>
          </box>
        </geometry>
        <material>
          <script>
            <name>Gazebo/Orange</name>
            <uri>file://media/materials/scripts/gazebo.material</uri>
          </script>
          <diffuse>1 0.375 0.125 1</diffuse>
          <ambient>1 0.375 0.125 1</ambient>
        </material>
      </visual>
      <visual name='base_link_fixed_joint_lump__caster_wheel1_link_visual_1'>
        <pose>-0.16 0.125 -0.04 0 0 0</pose>
        <geometry>
          <sphere>
            <radius>0.01</radius>
          </sphere>
        </geometry>
        <material>
          <script>
            <name>Gazebo/Red</name>
            <uri>file://media/materials/scripts/gazebo.material</uri>
          </script>
          <diffuse>1 1 1 1</diffuse>
          <ambient>1 1 1 1</ambient>
        </material>
      </visual>
      <visual name='base_link_fixed_joint_lump__connector_cw1_link_visual_2'>
        <pose>-0.16 0.125 -0.02 0 0 0</pose>
        <geometry>
          <cylinder>
            <length>0.021999999999999999</length>
            <radius>0.0050000000000000001</radius>
          </cylinder>
        </geometry>
        <material>
          <diffuse>0 0 0 1</diffuse>
          <ambient>0 0 0 1</ambient>
        </material>
      </visual>
      <visual name='base_link_fixed_joint_lump__caster_wheel2_link_visual_3'>
        <pose>-0.16 -0.125 -0.04 0 0 0</pose>
        <geometry>
          <sphere>
            <radius>0.01</radius>
          </sphere>
        </geometry>
        <material>
          <script>
            <name>Gazebo/Red</name>
            <uri>file://media/materials/scripts/gazebo.material</uri>
          </script>
          <diffuse>1 1 1 1</diffuse>
          <ambient>1 1 1 1</ambient>
        </material>
      </visual>
      <visual name='base_link_fixed_joint_lump__connector_cw2_link_visual_4'>
        <pose>-0.16 -0.125 -0.02 0 0 0</pose>
        <geometry>
          <cylinder>
            <length>0.021999999999999999</length>
            <radius>0.0050000000000000001</radius>
          </cylinder>
        </geometry>
        <material>
          <diffuse>0 0 0 1</diffuse>
          <ambient>0 0 0 1</ambient>
        </material>
      </visual>
      <visual name='base_link_fixed_joint_lump__caster_wheel3_link_visual_5'>
        <pose>0.13 0.125 -0.04 0 0 0</pose>
        <geometry>
          <sphere>
            <radius>0.01</radius>
          </sphere>
        </geometry>
        <material>
          <script>
            <name>Gazebo/Red</name>
            <uri>file://media/materials/scripts/gazebo.material</uri>
          </script>
          <diffuse>1 1 1 1</diffuse>
          <ambient>1 1 1 1</ambient>
        </material>
      </visual>
      <visual name='base_link_fixed_joint_lump__connector_cw3_link_visual_6'>
        <pose>0.13 0.125 -0.02 0 0 0</pose>
        <geometry>
          <cylinder>
            <length>0.021999999999999999</length>
            <radius>0.0050000000000000001</radius>
          </cylinder>
        </geometry>
        <material>
          <diffuse>0 0 0 1</diffuse>
          <ambient>0 0 0 1</ambient>
        </material>
      </visual>
      <visual name='base_link_fixed_joint_lump__caster_wheel4_link_visual_7'>
        <pose>0.13 -0.125 -0.04 0 0 0</pose>
        <geometry>
          <sphere>
            <radius>0.01</radius>
          </sphere>
        </geometry>
        <material>
          <script>
            <name>Gazebo/Red</name>
            <uri>file://media/materials/scripts/gazebo.material</uri>
          </script>
          <diffuse>1 1 1 1</diffuse>
          <ambient>1 1 1 1</ambient>
        </material>
      </visual>
      <visual name='base_link_fixed_joint_lump__connector_cw4_link_visual_8'>
        <pose>0.13 -0.125 -0.02 0 0 0</pose>
        <geometry>
          <cylinder>
            <length>0.021999999999999999</length>
            <radius>0.0050000000000000001</radius>
          </cylinder>
        </geometry>
        <material>
          <diffuse>0 0 0 1</diffuse>
          <ambient>0 0 0 1</ambient>
        </material>
      </visual>
      <visual name='base_link_fixed_joint_lump__stepper_link_visual_9'>
        <pose>0.165 0 0 0 0 0</pose>
        <geometry>
          <box>
            <size>0.02 0.02 0.01</size>
          </box>
        </geometry>
        <material>
          <script>
            <name>Gazebo/Green</name>
            <uri>file://media/materials/scripts/gazebo.material</uri>
          </script>
          <diffuse>0.125 0.25 1 1</diffuse>
          <ambient>0.125 0.25 1 1</ambient>
        </material>
      </visual>
    </link>
    <joint name='rotor_joint' type='revolute'>
      <pose relative_to='base_link'>0.165 0 0.01 0 0 0</pose>
      <parent>base_link</parent>
      <child>rotor_link</child>
      <axis>
        <xyz>0 0 1</xyz>
        <limit>
          <lower>-0.65449999999999997</lower>
          <upper>0.65449999999999997</upper>
          <effort>1</effort>
          <velocity>0.5</velocity>
        </limit>
        <dynamics>
          <spring_reference>0</spring_reference>
          <spring_stiffness>0</spring_stiffness>
        </dynamics>
      </axis>
    </joint>
    <link name='rotor_link'>
      <pose relative_to='rotor_joint'>0 0 0 0 0 0</pose>
      <inertial>
        <pose>1.447866287715299e-05 -0.01818182971156783 -0.01727272150785154 0 0 0</pose>
        <mass>0.11</mass>
        <inertia>
          <ixx>0.00051090616456135054</ixx>
          <ixy>2.8969924449557942e-09</ixy>
          <ixz>-2.6912177539044742e-06</ixz>
          <iyy>0.0038875846516195629</iyy>
          <iyz>-5.4561280044453713e-06</iyz>
          <izz>0.0038850022210399661</izz>
        </inertia>
      </inertial>
      <collision name='rotor_link_collision'>
        <pose>0 0 0 0 0 0</pose>
        <geometry>
          <cylinder>
            <length>0.01</length>
            <radius>0.0050000000000000001</radius>
          </cylinder>
        </geometry>
      </collision>
      <collision name='rotor_link_fixed_joint_lump__ultrasonic_link_collision_1'>
        <pose>0 -0.02 0 1.57 -5.551115123125783e-17 1.57</pose>
        <geometry>
          <box>
            <size>0.045 0.02 0.015</size>
          </box>
        </geometry>
      </collision>
      <visual name='rotor_link_visual'>
        <pose>0 0 0 0 0 0</pose>
        <geometry>
          <cylinder>
            <length>0.01</length>
            <radius>0.0050000000000000001</radius>
          </cylinder>
        </geometry>
        <material>
          <diffuse>1 0 0 1</diffuse>
          <ambient>1 0 0 1</ambient>
        </material>
      </visual>
      <visual name='rotor_link_fixed_joint_lump__ultrasonic_link_visual_1'>
        <pose>0 -0.02 0 1.57 -5.551115123125783e-17 1.57</pose>
        <geometry>
          <mesh>
            <scale>0.001 0.0004 0.0009</scale>
            <uri>package://gdgu_robot/meshes/ULTRASONIC_INFRARED.STL</uri>
          </mesh>
        </geometry>
        <material>
          <diffuse>0.125 0.25 1 1</diffuse>
          <ambient>0.125 0.25 1 1</ambient>
        </material>
      </visual>
      <sensor name='ultrasonic' type='gpu_lidar'>
        <update_rate>5</update_rate>
        <always_on>true</always_on>
        <visualize>true</visualize>
        <topic>ultrasonic_sensor</topic>
        <ray>
          <scan>
            <horizontal>
              <samples>1</samples>
              <resolution>1</resolution>
              <min_angle>0</min_angle>
              <max_angle>15</max_angle>
            </horizontal>
          </scan>
          <range>
            <min>0.029999999999999999</min>
            <max>0.40000000000000002</max>
            <resolution>0.02</resolution>
          </range>
          <noise>
            <type>gaussian</type>
            <mean>0.10000000000000001</mean>
            <stddev>0.0050000000000000001</stddev>
          </noise>
        </ray>
        <pose>0.0498805 -0.0200397 0.15004 1.57 -5.55112e-17 1.57</pose>
      </sensor>
    </link>
    <joint name='left_wheel' type='revolute'>
      <pose relative_to='base_link'>0 0.155 0 -1.570796326794896 0 0</pose>
      <parent>base_link</parent>
      <child>lfw_link</child>
      <axis>
        <xyz>0 0 1</xyz>
        <limit>
          <lower>-10000000000000000</lower>
          <upper>10000000000000000</upper>
        </limit>
        <dynamics>
          <spring_reference>0</spring_reference>
          <spring_stiffness>0</spring_stiffness>
        </dynamics>
      </axis>
    </joint>
    <link name='lfw_link'>
      <pose relative_to='left_wheel'>0 0 0 0 0 0</pose>
      <inertial>
        <pose>0 0 0 0 0 0</pose>
        <mass>0.5</mass>
        <inertia>
          <ixx>0.00032916666666666668</ixx>
          <ixy>0</ixy>
          <ixz>0</ixz>
          <iyy>0.00032916666666666668</iyy>
          <iyz>0</iyz>
          <izz>0.00062500000000000012</izz>
        </inertia>
      </inertial>
      <collision name='lfw_link_collision'>
        <pose>0 0 0 0 0 0</pose>
        <geometry>
          <sphere>
            <radius>0.050000000000000003</radius>
          </sphere>
        </geometry>
        <surface>
          <contact>
            <ode/>
          </contact>
          <friction>
            <ode/>
          </friction>
        </surface>
      </collision>
      <visual name='lfw_link_visual'>
        <pose>0 0 0 0 0 0</pose>
        <geometry>
          <cylinder>
            <length>0.02</length>
            <radius>0.050000000000000003</radius>
          </cylinder>
        </geometry>
        <material>
          <script>
            <name>Gazebo/Blue</name>
            <uri>file://media/materials/scripts/gazebo.material</uri>
          </script>
          <diffuse>0.25 0.25 1 1</diffuse>
          <ambient>0.25 0.25 1 1</ambient>
        </material>
      </visual>
    </link>
    <joint name='right_wheel' type='revolute'>
      <pose relative_to='base_link'>0 -0.155 0 1.570796326794896 0 0</pose>
      <parent>base_link</parent>
      <child>rfw_link</child>
      <axis>
        <xyz>0 0 -1</xyz>
        <limit>
          <lower>-10000000000000000</lower>
          <upper>10000000000000000</upper>
        </limit>
        <dynamics>
          <spring_reference>0</spring_reference>
          <spring_stiffness>0</spring_stiffness>
        </dynamics>
      </axis>
    </joint>
    <link name='rfw_link'>
      <pose relative_to='right_wheel'>0 0 0 0 0 0</pose>
      <inertial>
        <pose>0 0 0 0 0 0</pose>
        <mass>0.5</mass>
        <inertia>
          <ixx>0.00032916666666666668</ixx>
          <ixy>0</ixy>
          <ixz>0</ixz>
          <iyy>0.00032916666666666668</iyy>
          <iyz>0</iyz>
          <izz>0.00062500000000000012</izz>
        </inertia>
      </inertial>
      <collision name='rfw_link_collision'>
        <pose>0 0 0 0 0 0</pose>
        <geometry>
          <sphere>
            <radius>0.050000000000000003</radius>
          </sphere>
        </geometry>
        <surface>
          <contact>
            <ode/>
          </contact>
          <friction>
            <ode/>
          </friction>
        </surface>
      </collision>
      <visual name='rfw_link_visual'>
        <pose>0 0 0 0 0 0</pose>
        <geometry>
          <cylinder>
            <length>0.02</length>
            <radius>0.050000000000000003</radius>
          </cylinder>
        </geometry>
        <material>
          <script>
            <name>Gazebo/Blue</name>
            <uri>file://media/materials/scripts/gazebo.material</uri>
          </script>
          <diffuse>0.25 0.25 1 1</diffuse>
          <ambient>0.25 0.25 1 1</ambient>
        </material>
      </visual>
    </link>
    <plugin name='gz::sim::systems::DiffDrive' filename='gz-sim-diff-drive-system'>
      <ros>
        <remapping>cmd_vel:=/cmd_vel</remapping>
        <remapping>odom:=/odom</remapping>
      </ros>
      <left_joint>left_wheel</left_joint>
      <right_joint>right_wheel</right_joint>
      <wheel_separation>0.31</wheel_separation>
      <wheel_radius>0.05</wheel_radius>
      <odom_publish_frequency>100</odom_publish_frequency>
      <topic>cmd_vel</topic>
      <odom_topic>odom</odom_topic>
      <frame_id>odom</frame_id>
      <child_frame_id>base_link</child_frame_id>
      <max_linear_accelaration>1</max_linear_accelaration>
    </plugin>
    <plugin name='gz::sim::systems::JointStatePublisher' filename='gz-sim-joint-state-publisher-system'>
      <topic>joint_states</topic>
      <joint_name>left_wheel</joint_name>
      <joint_name>right_wheel</joint_name>
      <joint_name>rotor_joint</joint_name>
    </plugin>
    <frame name='base_footprint_joint' attached_to='base_link'>
      <pose>0 0 0 0 -0 0</pose>
    </frame>
    <frame name='base_footprint' attached_to='base_footprint_joint'/>
    <frame name='connector_cw1_joint' attached_to='caster_wheel1_link'>
      <pose>0 0 0.02 0 -0 0</pose>
    </frame>
    <frame name='connector_cw1_link' attached_to='connector_cw1_joint'/>
    <frame name='caster_wheel1_joint' attached_to='chassis_link'>
      <pose>0.015 0.125 -0.03 0 -0 0</pose>
    </frame>
    <frame name='caster_wheel1_link' attached_to='caster_wheel1_joint'/>
    <frame name='connector_cw2_joint' attached_to='caster_wheel2_link'>
      <pose>0 0 0.02 0 -0 0</pose>
    </frame>
    <frame name='connector_cw2_link' attached_to='connector_cw2_joint'/>
    <frame name='caster_wheel2_joint' attached_to='chassis_link'>
      <pose>0.015 -0.125 -0.03 0 -0 0</pose>
    </frame>
    <frame name='caster_wheel2_link' attached_to='caster_wheel2_joint'/>
    <frame name='connector_cw3_joint' attached_to='caster_wheel3_link'>
      <pose>0 0 0.02 0 -0 0</pose>
    </frame>
    <frame name='connector_cw3_link' attached_to='connector_cw3_joint'/>
    <frame name='caster_wheel3_joint' attached_to='chassis_link'>
      <pose>0.305 0.125 -0.03 0 -0 0</pose>
    </frame>
    <frame name='caster_wheel3_link' attached_to='caster_wheel3_joint'/>
    <frame name='connector_cw4_joint' attached_to='caster_wheel4_link'>
      <pose>0 0 0.02 0 -0 0</pose>
    </frame>
    <frame name='connector_cw4_link' attached_to='connector_cw4_joint'/>
    <frame name='caster_wheel4_joint' attached_to='chassis_link'>
      <pose>0.305 -0.125 -0.03 0 -0 0</pose>
    </frame>
    <frame name='caster_wheel4_link' attached_to='caster_wheel4_joint'/>
    <frame name='stepper_joint' attached_to='chassis_link'>
      <pose>0.34 0 0.01 0 -0 0</pose>
    </frame>
    <frame name='stepper_link' attached_to='stepper_joint'/>
    <frame name='ray_joint' attached_to='ultrasonic_link'>
      <pose>0 0.15 0.05 0 -0 0</pose>
    </frame>
    <frame name='ray_link' attached_to='ray_joint'/>
    <frame name='ultrasonic_joint' attached_to='rotor_link'>
      <pose>0 -0.02 0 1.57 -0 1.57</pose>
    </frame>
    <frame name='ultrasonic_link' attached_to='ultrasonic_joint'/>
    <frame name='chassis_joint' attached_to='base_link'>
      <pose>-0.175 0 -0.01 0 -0 0</pose>
    </frame>
    <frame name='chassis_link' attached_to='chassis_joint'/>
  </model>
</sdf>
