<?xml version="1.0" ?>
<!-- =================================================================================== -->
<!-- |    This document was autogenerated by xacro from robot.xacro                    | -->
<!-- |    EDITING THIS FILE BY HAND IS NOT RECOMMENDED                                 | -->
<!-- =================================================================================== -->
<robot name="gdgu_robot">
  <material name="white">
    <color rgba="1 1 1 1"/>
  </material>
  <material name="orange">
    <color rgba="1 0.3 0.1 1"/>
  </material>
  <material name="blue">
    <color rgba="0.2 0.2 1 1"/>
  </material>
  <material name="black">
    <color rgba="0 0 0 1"/>
  </material>
  <material name="red">
    <color rgba="1 0 0 1"/>
  </material>
  <!-- BASE LINK -->
  <link name="base_link">

    </link>
  <!-- BASE_FOOTPRINT LINK -->
  <joint name="base_footprint_joint" type="fixed">
    <parent link="base_link"/>
    <child link="base_footprint"/>
    <origin rpy="0 0 0" xyz="0 0 0"/>
  </joint>
  <link name="base_footprint">
    </link>
  <!-- CHASSIS LINK -->
  <joint name="chassis_joint" type="fixed">
    <parent link="base_link"/>
    <child link="chassis_link"/>
    <origin xyz="-0.175 0 -0.01"/>
  </joint>
  <link name="chassis_link">
    <visual>
      <origin xyz="0.175 0 0.001"/>
      <geometry>
        <box size="0.35 0.29 0.002"/>
      </geometry>
      <material name="orange"/>
    </visual>
    <collision>
      <origin xyz="0.175 0 0.001"/>
      <geometry>
        <box size="0.35 0.29 0.002"/>
      </geometry>
    </collision>
    <inertial>
      <origin rpy="0 0 0" xyz="0.175 0 0.001"/>
      <mass value="2.0"/>
      <inertia ixx="0.014017333333333333" ixy="0.0" ixz="0.0" iyy="0.02041733333333333" iyz="0.0" izz="0.03443333333333333"/>
    </inertial>
  </link>
  <gazebo reference="chassis_link">
    <material>Gazebo/Orange</material>
  </gazebo>
  <!-- LEFT WHEEL LINK -->
  <joint name="left_wheel" type="continuous">
    <parent link="base_link"/>
    <child link="lfw_link"/>
    <origin rpy="-1.5707963267948966 0 0" xyz="0 0.155 0"/>
    <axis xyz="0 0 1"/>
  </joint>
  <link name="lfw_link">
    <visual>
      <geometry>
        <cylinder length="0.02" radius="0.05"/>
      </geometry>
      <material name="blue"/>
    </visual>
    <collision>
      <geometry>
        <sphere radius="0.05"/>
      </geometry>
    </collision>
    <inertial>
      <origin rpy="0 0 0" xyz="0 0 0"/>
      <mass value="0.5"/>
      <inertia ixx="0.0003291666666666667" ixy="0.0" ixz="0.0" iyy="0.0003291666666666667" iyz="0.0" izz="0.0006250000000000001"/>
    </inertial>
  </link>
  <gazebo reference="lfw_link">
    <material>Gazebo/Blue</material>
  </gazebo>
  <!-- RIGHT WHEEL LINK -->
  <joint name="right_wheel" type="continuous">
    <parent link="base_link"/>
    <child link="rfw_link"/>
    <origin rpy="1.5707963267948966 0 0" xyz="0 -0.155 0"/>
    <axis xyz="0 0 -1"/>
  </joint>
  <link name="rfw_link">
    <visual>
      <geometry>
        <cylinder length="0.02" radius="0.05"/>
      </geometry>
      <material name="blue"/>
    </visual>
    <collision>
      <geometry>
        <sphere radius="0.05"/>
      </geometry>
    </collision>
    <inertial>
      <origin rpy="0 0 0" xyz="0 0 0"/>
      <mass value="0.5"/>
      <inertia ixx="0.0003291666666666667" ixy="0.0" ixz="0.0" iyy="0.0003291666666666667" iyz="0.0" izz="0.0006250000000000001"/>
    </inertial>
  </link>
  <gazebo reference="rfw_link">
    <material>Gazebo/Blue</material>
  </gazebo>
  <!--castor wheels-->
  <joint name="caster_wheel1_joint" type="fixed">
    <parent link="chassis_link"/>
    <child link="caster_wheel1_link"/>
    <origin xyz="0.015 0.125 -0.03"/>
  </joint>
  <link name="caster_wheel1_link">
    <visual>
      <geometry>
        <sphere radius="0.01"/>
      </geometry>
      <material name="white"/>
    </visual>
    <collision>
      <geometry>
        <sphere radius="0.01"/>
      </geometry>
    </collision>
    <inertial>
      <origin rpy="0 0 0" xyz="0 0 0"/>
      <mass value="0.01"/>
      <inertia ixx="4.0000000000000003e-07" ixy="0.0" ixz="0.0" iyy="4.0000000000000003e-07" iyz="0.0" izz="4.0000000000000003e-07"/>
    </inertial>
  </link>
  <gazebo reference="caster_wheel1_link">
    <material>Gazebo/Red</material>
    <mu1 value="0.001"/>
    <mu2 value="0.001"/>
  </gazebo>
  <joint name="caster_wheel2_joint" type="fixed">
    <parent link="chassis_link"/>
    <child link="caster_wheel2_link"/>
    <origin xyz="0.015 -0.125 -0.03"/>
  </joint>
  <link name="caster_wheel2_link">
    <visual>
      <geometry>
        <sphere radius="0.01"/>
      </geometry>
      <material name="white"/>
    </visual>
    <collision>
      <geometry>
        <sphere radius="0.01"/>
      </geometry>
    </collision>
    <inertial>
      <origin rpy="0 0 0" xyz="0 0 0"/>
      <mass value="0.01"/>
      <inertia ixx="4.0000000000000003e-07" ixy="0.0" ixz="0.0" iyy="4.0000000000000003e-07" iyz="0.0" izz="4.0000000000000003e-07"/>
    </inertial>
  </link>
  <gazebo reference="caster_wheel2_link">
    <material>Gazebo/Red</material>
    <mu1 value="0.001"/>
    <mu2 value="0.001"/>
  </gazebo>
  <joint name="caster_wheel3_joint" type="fixed">
    <parent link="chassis_link"/>
    <child link="caster_wheel3_link"/>
    <origin xyz="0.305 0.125 -0.03"/>
  </joint>
  <link name="caster_wheel3_link">
    <visual>
      <geometry>
        <sphere radius="0.01"/>
      </geometry>
      <material name="white"/>
    </visual>
    <collision>
      <geometry>
        <sphere radius="0.01"/>
      </geometry>
    </collision>
    <inertial>
      <origin rpy="0 0 0" xyz="0 0 0"/>
      <mass value="0.01"/>
      <inertia ixx="4.0000000000000003e-07" ixy="0.0" ixz="0.0" iyy="4.0000000000000003e-07" iyz="0.0" izz="4.0000000000000003e-07"/>
    </inertial>
  </link>
  <gazebo reference="caster_wheel3_link">
    <material>Gazebo/Red</material>
    <mu1 value="0.001"/>
    <mu2 value="0.001"/>
  </gazebo>
  <joint name="caster_wheel4_joint" type="fixed">
    <parent link="chassis_link"/>
    <child link="caster_wheel4_link"/>
    <origin xyz="0.305 -0.125 -0.03"/>
  </joint>
  <link name="caster_wheel4_link">
    <visual>
      <geometry>
        <sphere radius="0.01"/>
      </geometry>
      <material name="white"/>
    </visual>
    <collision>
      <geometry>
        <sphere radius="0.01"/>
      </geometry>
    </collision>
    <inertial>
      <origin rpy="0 0 0" xyz="0 0 0"/>
      <mass value="0.01"/>
      <inertia ixx="4.0000000000000003e-07" ixy="0.0" ixz="0.0" iyy="4.0000000000000003e-07" iyz="0.0" izz="4.0000000000000003e-07"/>
    </inertial>
  </link>
  <gazebo reference="caster_wheel4_link">
    <material>Gazebo/Red</material>
    <mu1 value="0.001"/>
    <mu2 value="0.001"/>
  </gazebo>
  <joint name="connector_cw1_joint" type="fixed">
    <parent link="caster_wheel1_link"/>
    <child link="connector_cw1_link"/>
    <origin rpy="0 0 0" xyz="0.0 0.0 0.02"/>
  </joint>
  <link name="connector_cw1_link">
    <visual>
      <geometry>
        <cylinder length="0.022" radius="0.005"/>
      </geometry>
      <material name="black"/>
    </visual>
    <collision>
      <geometry>
        <cylinder length="0.022" radius="0.005"/>
      </geometry>
    </collision>
    <inertial>
      <origin rpy="0.0 0.0 0.0" xyz="0.0 0.0 0.0"/>
      <mass value="0.1"/>
      <inertia ixx="4.6583333333333325e-06" ixy="0.0" ixz="0.0" iyy="4.6583333333333325e-06" iyz="0.0" izz="1.25e-06"/>
    </inertial>
  </link>
  <!-- Connector for castor wheel 2 -->
  <joint name="connector_cw2_joint" type="fixed">
    <parent link="caster_wheel2_link"/>
    <child link="connector_cw2_link"/>
    <origin rpy="0 0 0" xyz="0.0 0.0 0.02"/>
  </joint>
  <link name="connector_cw2_link">
    <visual>
      <geometry>
        <cylinder length="0.022" radius="0.005"/>
      </geometry>
      <material name="black"/>
    </visual>
    <collision>
      <geometry>
        <cylinder length="0.022" radius="0.005"/>
      </geometry>
    </collision>
    <inertial>
      <origin rpy="0.0 0.0 0.0" xyz="0.0 0.0 0.0"/>
      <mass value="0.1"/>
      <inertia ixx="4.6583333333333325e-06" ixy="0.0" ixz="0.0" iyy="4.6583333333333325e-06" iyz="0.0" izz="1.25e-06"/>
    </inertial>
  </link>
  <!-- Connector for castor wheel 3 -->
  <joint name="connector_cw3_joint" type="fixed">
    <parent link="caster_wheel3_link"/>
    <child link="connector_cw3_link"/>
    <origin rpy="0 0 0" xyz="0.0 0.0 0.02"/>
  </joint>
  <link name="connector_cw3_link">
    <visual>
      <geometry>
        <cylinder length="0.022" radius="0.005"/>
      </geometry>
      <material name="black"/>
    </visual>
    <collision>
      <geometry>
        <cylinder length="0.022" radius="0.005"/>
      </geometry>
    </collision>
    <inertial>
      <origin rpy="0.0 0.0 0.0" xyz="0.0 0.0 0.0"/>
      <mass value="0.1"/>
      <inertia ixx="4.6583333333333325e-06" ixy="0.0" ixz="0.0" iyy="4.6583333333333325e-06" iyz="0.0" izz="1.25e-06"/>
    </inertial>
  </link>
  <!-- Connector for castor wheel 4 -->
  <joint name="connector_cw4_joint" type="fixed">
    <parent link="caster_wheel4_link"/>
    <child link="connector_cw4_link"/>
    <origin rpy="0 0 0" xyz="0.0 0.0 0.02"/>
  </joint>
  <link name="connector_cw4_link">
    <visual>
      <geometry>
        <cylinder length="0.022" radius="0.005"/>
      </geometry>
      <material name="black"/>
    </visual>
    <collision>
      <geometry>
        <cylinder length="0.022" radius="0.005"/>
      </geometry>
    </collision>
    <inertial>
      <origin rpy="0.0 0.0 0.0" xyz="0.0 0.0 0.0"/>
      <mass value="0.1"/>
      <inertia ixx="4.6583333333333325e-06" ixy="0.0" ixz="0.0" iyy="4.6583333333333325e-06" iyz="0.0" izz="1.25e-06"/>
    </inertial>
  </link>
  <gazebo>
    <plugin filename="gz-sim-diff-drive-system" name="gz::sim::systems::DiffDrive">
      <!--Wheel Info-->
      <left_joint>left_wheel</left_joint>
      <right_joint>right_wheel</right_joint>
      <wheel_separation>0.31</wheel_separation>
      <wheel_radius>0.05</wheel_radius>
      <!--input-->
      <odom_publish_frequency>100</odom_publish_frequency>
      <topic>cmd_vel</topic>
      <!--output "what needs to be shown in the output"-->
      <odom_topic>odom</odom_topic>
      <!--limits "set according to the motor requirements"-->
      <max_linear_acceleration>1</max_linear_acceleration>
    </plugin>
    <plugin filename="gz-sim-joint-state-publisher-system" name="gz::sim::systems::JointStatePublisher">
      <topic>joint_states</topic>
      <joint_name>left_wheel</joint_name>
      <joint_name>right_wheel</joint_name>
    </plugin>
  </gazebo>
</robot>
