<sdf version='1.9'>
  <model name='gdgu_robot'>
    <link name='base_link'>
      <inertial>
        <pose>-0.007021276595744697 0 -0.015 0 0 0</pose>
        <mass>0.93999999999999995</mass>
        <inertia>
          <ixx>0.01045256666666667</ixx>
          <ixy>0</ixy>
          <ixz>-4.4999999999999739e-05</ixz>
          <iyy>0.01448122624113476</iyy>
          <iyz>0</iyz>
          <izz>0.024793592907801431</izz>
        </inertia>
      </inertial>
      <collision name='base_link_fixed_joint_lump__chassis_link_collision'>
        <pose>0 0 -0.009000000000000001 0 0 0</pose>
        <geometry>
          <box>
            <size>0.35 0.29 0.002</size>
          </box>
        </geometry>
        <surface>
          <contact>
            <ode/>
          </contact>
          <friction>
            <ode/>
          </friction>
        </surface>
      </collision>
      <collision name='base_link_fixed_joint_lump__caster_wheel1_link_collision_1'>
        <pose>-0.16 0.125 -0.04 0 0 0</pose>
        <geometry>
          <sphere>
            <radius>0.01</radius>
          </sphere>
        </geometry>
        <surface>
          <contact>
            <ode/>
          </contact>
          <friction>
            <ode>
              <mu>0.001</mu>
              <mu2>0.001</mu2>
            </ode>
          </friction>
        </surface>
      </collision>
      <collision name='base_link_fixed_joint_lump__connector_cw1_link_collision_2'>
        <pose>-0.16 0.125 -0.02 0 0 0</pose>
        <geometry>
          <cylinder>
            <length>0.021999999999999999</length>
            <radius>0.0050000000000000001</radius>
          </cylinder>
        </geometry>
      </collision>
      <collision name='base_link_fixed_joint_lump__caster_wheel2_link_collision_3'>
        <pose>-0.16 -0.125 -0.04 0 0 0</pose>
        <geometry>
          <sphere>
            <radius>0.01</radius>
          </sphere>
        </geometry>
        <surface>
          <contact>
            <ode/>
          </contact>
          <friction>
            <ode>
              <mu>0.001</mu>
              <mu2>0.001</mu2>
            </ode>
          </friction>
        </surface>
      </collision>
      <collision name='base_link_fixed_joint_lump__connector_cw2_link_collision_4'>
        <pose>-0.16 -0.125 -0.02 0 0 0</pose>
        <geometry>
          <cylinder>
            <length>0.021999999999999999</length>
            <radius>0.0050000000000000001</radius>
          </cylinder>
        </geometry>
      </collision>
      <collision name='base_link_fixed_joint_lump__caster_wheel3_link_collision_5'>
        <pose>0.13 0.125 -0.04 0 0 0</pose>
        <geometry>
          <sphere>
            <radius>0.01</radius>
          </sphere>
        </geometry>
        <surface>
          <contact>
            <ode/>
          </contact>
          <friction>
            <ode>
              <mu>0.001</mu>
              <mu2>0.001</mu2>
            </ode>
          </friction>
        </surface>
      </collision>
      <collision name='base_link_fixed_joint_lump__connector_cw3_link_collision_6'>
        <pose>0.13 0.125 -0.02 0 0 0</pose>
        <geometry>
          <cylinder>
            <length>0.021999999999999999</length>
            <radius>0.0050000000000000001</radius>
          </cylinder>
        </geometry>
      </collision>
      <collision name='base_link_fixed_joint_lump__caster_wheel4_link_collision_7'>
        <pose>0.13 -0.125 -0.04 0 0 0</pose>
        <geometry>
          <sphere>
            <radius>0.01</radius>
          </sphere>
        </geometry>
        <surface>
          <contact>
            <ode/>
          </contact>
          <friction>
            <ode>
              <mu>0.001</mu>
              <mu2>0.001</mu2>
            </ode>
          </friction>
        </surface>
      </collision>
      <collision name='base_link_fixed_joint_lump__connector_cw4_link_collision_8'>
        <pose>0.13 -0.125 -0.02 0 0 0</pose>
        <geometry>
          <cylinder>
            <length>0.021999999999999999</length>
            <radius>0.0050000000000000001</radius>
          </cylinder>
        </geometry>
      </collision>
      <visual name='base_link_fixed_joint_lump__chassis_link_visual'>
        <pose>0 0 -0.009000000000000001 0 0 0</pose>
        <geometry>
          <box>
            <size>0.35 0.29 0.002</size>
          </box>
        </geometry>
        <material>
          <script>
            <name>Gazebo/Orange</name>
            <uri>file://media/materials/scripts/gazebo.material</uri>
          </script>
          <diffuse>1 0.375 0.125 1</diffuse>
          <ambient>1 0.375 0.125 1</ambient>
        </material>
      </visual>
      <visual name='base_link_fixed_joint_lump__caster_wheel1_link_visual_1'>
        <pose>-0.16 0.125 -0.04 0 0 0</pose>
        <geometry>
          <sphere>
            <radius>0.01</radius>
          </sphere>
        </geometry>
        <material>
          <script>
            <name>Gazebo/Red</name>
            <uri>file://media/materials/scripts/gazebo.material</uri>
          </script>
          <diffuse>1 1 1 1</diffuse>
          <ambient>1 1 1 1</ambient>
        </material>
      </visual>
      <visual name='base_link_fixed_joint_lump__connector_cw1_link_visual_2'>
        <pose>-0.16 0.125 -0.02 0 0 0</pose>
        <geometry>
          <cylinder>
            <length>0.021999999999999999</length>
            <radius>0.0050000000000000001</radius>
          </cylinder>
        </geometry>
        <material>
          <diffuse>0 0 0 1</diffuse>
          <ambient>0 0 0 1</ambient>
        </material>
      </visual>
      <visual name='base_link_fixed_joint_lump__caster_wheel2_link_visual_3'>
        <pose>-0.16 -0.125 -0.04 0 0 0</pose>
        <geometry>
          <sphere>
            <radius>0.01</radius>
          </sphere>
        </geometry>
        <material>
          <script>
            <name>Gazebo/Red</name>
            <uri>file://media/materials/scripts/gazebo.material</uri>
          </script>
          <diffuse>1 1 1 1</diffuse>
          <ambient>1 1 1 1</ambient>
        </material>
      </visual>
      <visual name='base_link_fixed_joint_lump__connector_cw2_link_visual_4'>
        <pose>-0.16 -0.125 -0.02 0 0 0</pose>
        <geometry>
          <cylinder>
            <length>0.021999999999999999</length>
            <radius>0.0050000000000000001</radius>
          </cylinder>
        </geometry>
        <material>
          <diffuse>0 0 0 1</diffuse>
          <ambient>0 0 0 1</ambient>
        </material>
      </visual>
      <visual name='base_link_fixed_joint_lump__caster_wheel3_link_visual_5'>
        <pose>0.13 0.125 -0.04 0 0 0</pose>
        <geometry>
          <sphere>
            <radius>0.01</radius>
          </sphere>
        </geometry>
        <material>
          <script>
            <name>Gazebo/Red</name>
            <uri>file://media/materials/scripts/gazebo.material</uri>
          </script>
          <diffuse>1 1 1 1</diffuse>
          <ambient>1 1 1 1</ambient>
        </material>
      </visual>
      <visual name='base_link_fixed_joint_lump__connector_cw3_link_visual_6'>
        <pose>0.13 0.125 -0.02 0 0 0</pose>
        <geometry>
          <cylinder>
            <length>0.021999999999999999</length>
            <radius>0.0050000000000000001</radius>
          </cylinder>
        </geometry>
        <material>
          <diffuse>0 0 0 1</diffuse>
          <ambient>0 0 0 1</ambient>
        </material>
      </visual>
      <visual name='base_link_fixed_joint_lump__caster_wheel4_link_visual_7'>
        <pose>0.13 -0.125 -0.04 0 0 0</pose>
        <geometry>
          <sphere>
            <radius>0.01</radius>
          </sphere>
        </geometry>
        <material>
          <script>
            <name>Gazebo/Red</name>
            <uri>file://media/materials/scripts/gazebo.material</uri>
          </script>
          <diffuse>1 1 1 1</diffuse>
          <ambient>1 1 1 1</ambient>
        </material>
      </visual>
      <visual name='base_link_fixed_joint_lump__connector_cw4_link_visual_8'>
        <pose>0.13 -0.125 -0.02 0 0 0</pose>
        <geometry>
          <cylinder>
            <length>0.021999999999999999</length>
            <radius>0.0050000000000000001</radius>
          </cylinder>
        </geometry>
        <material>
          <diffuse>0 0 0 1</diffuse>
          <ambient>0 0 0 1</ambient>
        </material>
      </visual>
    </link>
    <joint name='left_wheel' type='revolute'>
      <pose relative_to='base_link'>0 0.155 0 -1.570796326794896 0 0</pose>
      <parent>base_link</parent>
      <child>lfw_link</child>
      <axis>
        <xyz>0 0 1</xyz>
        <limit>
          <lower>-10000000000000000</lower>
          <upper>10000000000000000</upper>
        </limit>
        <dynamics>
          <spring_reference>0</spring_reference>
          <spring_stiffness>0</spring_stiffness>
        </dynamics>
      </axis>
    </joint>
    <link name='lfw_link'>
      <pose relative_to='left_wheel'>0 0 0 0 0 0</pose>
      <inertial>
        <pose>0 0 0 0 0 0</pose>
        <mass>0.5</mass>
        <inertia>
          <ixx>0.00032916666666666668</ixx>
          <ixy>0</ixy>
          <ixz>0</ixz>
          <iyy>0.00032916666666666668</iyy>
          <iyz>0</iyz>
          <izz>0.00062500000000000012</izz>
        </inertia>
      </inertial>
      <collision name='lfw_link_collision'>
        <pose>0 0 0 0 0 0</pose>
        <geometry>
          <sphere>
            <radius>0.050000000000000003</radius>
          </sphere>
        </geometry>
        <surface>
          <contact>
            <ode/>
          </contact>
          <friction>
            <ode/>
          </friction>
        </surface>
      </collision>
      <visual name='lfw_link_visual'>
        <pose>0 0 0 0 0 0</pose>
        <geometry>
          <cylinder>
            <length>0.02</length>
            <radius>0.050000000000000003</radius>
          </cylinder>
        </geometry>
        <material>
          <script>
            <name>Gazebo/Blue</name>
            <uri>file://media/materials/scripts/gazebo.material</uri>
          </script>
          <diffuse>0.25 0.25 1 1</diffuse>
          <ambient>0.25 0.25 1 1</ambient>
        </material>
      </visual>
    </link>
    <joint name='right_wheel' type='revolute'>
      <pose relative_to='base_link'>0 -0.155 0 1.570796326794896 0 0</pose>
      <parent>base_link</parent>
      <child>rfw_link</child>
      <axis>
        <xyz>0 0 -1</xyz>
        <limit>
          <lower>-10000000000000000</lower>
          <upper>10000000000000000</upper>
        </limit>
        <dynamics>
          <spring_reference>0</spring_reference>
          <spring_stiffness>0</spring_stiffness>
        </dynamics>
      </axis>
    </joint>
    <link name='rfw_link'>
      <pose relative_to='right_wheel'>0 0 0 0 0 0</pose>
      <inertial>
        <pose>0 0 0 0 0 0</pose>
        <mass>0.5</mass>
        <inertia>
          <ixx>0.00032916666666666668</ixx>
          <ixy>0</ixy>
          <ixz>0</ixz>
          <iyy>0.00032916666666666668</iyy>
          <iyz>0</iyz>
          <izz>0.00062500000000000012</izz>
        </inertia>
      </inertial>
      <collision name='rfw_link_collision'>
        <pose>0 0 0 0 0 0</pose>
        <geometry>
          <sphere>
            <radius>0.050000000000000003</radius>
          </sphere>
        </geometry>
        <surface>
          <contact>
            <ode/>
          </contact>
          <friction>
            <ode/>
          </friction>
        </surface>
      </collision>
      <visual name='rfw_link_visual'>
        <pose>0 0 0 0 0 0</pose>
        <geometry>
          <cylinder>
            <length>0.02</length>
            <radius>0.050000000000000003</radius>
          </cylinder>
        </geometry>
        <material>
          <script>
            <name>Gazebo/Blue</name>
            <uri>file://media/materials/scripts/gazebo.material</uri>
          </script>
          <diffuse>0.25 0.25 1 1</diffuse>
          <ambient>0.25 0.25 1 1</ambient>
        </material>
      </visual>
    </link>
    <plugin name='gz::sim::systems::DiffDrive' filename='gz-sim-diff-drive-system'>
      <left_joint>left_wheel</left_joint>
      <right_joint>right_wheel</right_joint>
      <wheel_separation>0.31</wheel_separation>
      <wheel_radius>0.05</wheel_radius>
      <odom_publish_frequency>100</odom_publish_frequency>
      <topic>cmd_vel</topic>
      <odom_topic>odom</odom_topic>
      <frame_id>odom</frame_id>
      <child_frame_id>base_link</child_frame_id>
      <max_linear_accelaration>1</max_linear_accelaration>
    </plugin>
    <plugin name='gz::sim::systems::JointStatePublisher' filename='gz-sim-joint-state-publisher-system'>
      <topic>joint_states</topic>
      <joint_name>left_wheel</joint_name>
      <joint_name>right_wheel</joint_name>
      <joint_name>rotor_joint</joint_name>
    </plugin>
    <frame name='base_footprint_joint' attached_to='base_link'>
      <pose>0 0 0 0 -0 0</pose>
    </frame>
    <frame name='base_footprint' attached_to='base_footprint_joint'/>
    <frame name='connector_cw1_joint' attached_to='caster_wheel1_link'>
      <pose>0 0 0.02 0 -0 0</pose>
    </frame>
    <frame name='connector_cw1_link' attached_to='connector_cw1_joint'/>
    <frame name='caster_wheel1_joint' attached_to='chassis_link'>
      <pose>0.015 0.125 -0.03 0 -0 0</pose>
    </frame>
    <frame name='caster_wheel1_link' attached_to='caster_wheel1_joint'/>
    <frame name='connector_cw2_joint' attached_to='caster_wheel2_link'>
      <pose>0 0 0.02 0 -0 0</pose>
    </frame>
    <frame name='connector_cw2_link' attached_to='connector_cw2_joint'/>
    <frame name='caster_wheel2_joint' attached_to='chassis_link'>
      <pose>0.015 -0.125 -0.03 0 -0 0</pose>
    </frame>
    <frame name='caster_wheel2_link' attached_to='caster_wheel2_joint'/>
    <frame name='connector_cw3_joint' attached_to='caster_wheel3_link'>
      <pose>0 0 0.02 0 -0 0</pose>
    </frame>
    <frame name='connector_cw3_link' attached_to='connector_cw3_joint'/>
    <frame name='caster_wheel3_joint' attached_to='chassis_link'>
      <pose>0.305 0.125 -0.03 0 -0 0</pose>
    </frame>
    <frame name='caster_wheel3_link' attached_to='caster_wheel3_joint'/>
    <frame name='connector_cw4_joint' attached_to='caster_wheel4_link'>
      <pose>0 0 0.02 0 -0 0</pose>
    </frame>
    <frame name='connector_cw4_link' attached_to='connector_cw4_joint'/>
    <frame name='caster_wheel4_joint' attached_to='chassis_link'>
      <pose>0.305 -0.125 -0.03 0 -0 0</pose>
    </frame>
    <frame name='caster_wheel4_link' attached_to='caster_wheel4_joint'/>
    <frame name='chassis_joint' attached_to='base_link'>
      <pose>-0.175 0 -0.01 0 -0 0</pose>
    </frame>
    <frame name='chassis_link' attached_to='chassis_joint'/>
  </model>
</sdf>
