<?xml version="1.0"?>
<robot name="gdgu_robot" xmlns:xacro="http://ros.org/wiki/xacro">

    <xacro:include filename="robot_inertia.xacro"/>
    
    <!--joint and link for a stepper motor-->
    <joint name="stepper_joint" type="fixed">
        <parent link="chassis_link"/>
        <child link="stepper_link"/>
        <origin xyz="0.34 0.0 0.01" rpy="0.0 0.0 0.0"/>
    </joint>
    <link name="stepper_link">
        <visual>
            <geometry>
                <box size="0.02 0.02 0.01"/>
            </geometry>
            <material name="sensor_blue"/>
        </visual>
        <collision>
            <geometry>
                <box size="0.02 0.01 0.02"/>
            </geometry>
        </collision>  
        <xacro:inertial_box mass="0.1" x="0.02" y="0.02" z="0.01">
            <origin xyz="0.34 0.0 0.01" rpy="0.0 0.0 0.0"/>
        </xacro:inertial_box>       
    </link>
     <gazebo reference="stepper_link">
        <material>Gazebo/Black</material>
    </gazebo>

    <joint name="rotor_joint" type="revolute">
        <parent link="stepper_link"/>
        <child link="rotor_link"/>
        <origin xyz="0.0 0.0 0.01" rpy="0.0 0.0 0.0"/>
        <axis xyz="0 0 1"/> 
        <limit effort="1" velocity="0.5" lower="-0.6545" upper="0.6545"/>  
    </joint>

    <link name="rotor_link">
        <visual>
            <geometry>
                <cylinder radius=".005" length="0.01"/>
            </geometry>
            <material name="material_lightgrey"/>
        </visual>
        <collision>
            <geometry>
                <cylinder radius=".005" length="0.01"/>
            </geometry>
        </collision>
        <xacro:inertial_cylinder mass="0.01" length="0.01" radius="0.005">
            <origin xyz="0 0 0.01" rpy="0 0 0"/>
        </xacro:inertial_cylinder>
    </link>

    <!--joint and link for ultrasonic sensor-->
    
    <joint name="ultrasonic_joint" type="fixed">
        <parent link="rotor_link"/>
        <child link="ultrasonic_link"/>
        <origin xyz="0.0 -0.02 0.0" rpy="1.57 0 1.57"/>  
    </joint>
    <link name="ultrasonic_link">
        <visual>
            <geometry>
                <mesh filename="package://gdgu_robot/meshes/ULTRASONIC_INFRARED.STL" scale="0.001 0.0004 0.0009"/>
            </geometry>
            <material name="sensor_blue"/>
        </visual>
        <collision>
            <geometry>
                <box size="0.045 0.02 0.015"/>
            </geometry>
        </collision>
        <inertial>
            <mass value="0.1" />
            <origin xyz="0 -0.02 0.0" rpy="1.57 0 -1.57"/>
            <inertia ixx="0.003881243" ixy="0.0" ixz="0.0"
                     iyy="0.000498940" iyz="0.0"
                     izz="0.003879257" />
        </inertial>
    </link>


    <gazebo reference="ultrasonic_link">
        <sensor name="ultrasonic" type="gpu_lidar">
            <pose> 0 -0.02 0 -1.57 0 1.57 </pose>
            <update_rate>5</update_rate>
            <always_on>1</always_on>        
            <visualize>1</visualize>
            <ray>
                <scan>
                    <horizontal>
                        <samples>1</samples>
                        <resolution>1</resolution>
                        <min_angle>-0.309</min_angle>
                        <max_angle>0.309</max_angle>
                    </horizontal>
                </scan>
                <range>
                    <min>0.03</min>
                    <max>4.0</max>
                    <resolution>0.02</resolution>
                </range>
                <noise>
                    <type>gaussian</type>
                    <mean>0.1</mean>
                    <stddev>0.005</stddev>
                </noise>
            </ray>
            <topic>scan</topic>
            <gz_frame_id>ultrasonic_link</gz_frame_id>
        </sensor>
        
    </gazebo>
    
</robot>